Workbook
Name cur_scenario: #REF!
Name model_columns: #REF!
Name model_data: #REF!
Name model_rows: #REF!
Name scn_columns: #REF!
Name scn_data: #REF!
Name scn_rows: #REF!

Sheet Summary
B1: Forecast summary: Annual
B3: Room demand | O3: Room demand
B4: Daily levels | O4: Daily levels
C6: 2019 | D6: 2020 | E6: 2021 | F6: 2022 | G6: 2023 | H6: 2024 | I6: 2025 | J6: 2026 | K6: 2027 | L6: 2028 | M6: 2029 | P6: 2019 | Q6: 2020 | R6: 2021 | S6: 2022 | T6: 2023 | U6: 2024 | V6: 2025 | W6: 2026 | X6: 2027 | Y6: 2028 | Z6: 2029
B8: California | C8: 407202.73 | D8: 250110.57 | E8: 328241.41 | F8: 377315.35 | G8: 380050.73 | H8: =California!D$16 -> 382616.85 | I8: =California!D$17 -> 385856.03 | J8: =California!D$18 -> 394474.17 | K8: =California!D$19 -> 397557.67 | L8: =California!D$20 -> 404532.89 | M8: =California!D$21 -> 411595.72 | O8: California | P8: 0.030125753 | Q8: -0.38578366 | R8: 0.3123852 | S8: 0.14950565 | T8: 0.0072495898 | U8: =(H8-G8)/G8 -> 0.0067520347 | V8: =(I8-H8)/H8 -> 0.0084658471 | W8: =(J8-I8)/I8 -> 0.022335118 | X8: =(K8-J8)/J8 -> 0.0078167411 | Y8: =(L8-K8)/K8 -> 0.017545173 | Z8: =(M8-L8)/L8 -> 0.017459236
B9: Gateway Regions* | C9: =C17+C19+C21+C22 -> 278551.11 | D9: =D17+D19+D21+D22 -> 150621.69 | E9: =E17+E19+E21+E22 -> 202174.57 | F9: =F17+F19+F21+F22 -> 249151.45 | G9: =G17+G19+G21+G22 -> 255187.68 | H9: =H17+H19+H21+H22 -> 258085.3 | I9: =I17+I19+I21+I22 -> 259775.85 | J9: =J17+J19+J21+J22 -> 265739.92 | ... M9: =M17+M19+M21+M22 -> 276952.68 | O9: Gateway Regions* | P9: 0.026331096 | Q9: -0.4592673 | R9: 0.34226726 | S9: 0.23235803 | T9: 0.024227116 | U9: 0.011354878 | V9: 0.0065503707 | W9: 0.022958487 | X9: 0.005526547 | Y9: 0.018207276 | Z9: 0.017932661
B10: All Other Regions** | C10: =C11+C12+C13+C14+C15+C16+C18+C20 -> 128813.27 | D10: =D11+D12+D13+D14+D15+D16+D18+D20 -> 100517.39 | E10: =E11+E12+E13+E14+E15+E16+E18+E20 -> 126919.3 | F10: =F11+F12+F13+F14+F15+F16+F18+F20 -> 128193.78 | G10: =G11+G12+G13+G14+G15+G16+G18+G20 -> 124863.06 | H10: =H11+H12+H13+H14+H15+H16+H18+H20 -> 124531.55 | I10: =I11+I12+I13+I14+I15+I16+I18+I20 -> 126080.17 | J10: =J11+J12+J13+J14+J15+J16+J18+J20 -> 128734.25 | ... M10: =M11+M12+M13+M14+M15+M16+M18+M20 -> 134643.04 | O10: All Other Regions** | P10: 0.038438711 | Q10: -0.22667994 | R10: 0.26714509 | S10: 0.01663452 | T10: -0.025754832 | U10: -0.0026549816 | V10: 0.012435574 | W10: 0.021050728 | X10: 0.012544278 | Y10: 0.0161879 | Z10: 0.016486814
B11: Central Coast | C11: 29638.341 | D11: 20579.836 | E11: 27288.446 | F11: 29334.692 | G11: 28532.373 | H11: ='Central Coast'!D$16 -> 28777.815 | I11: ='Central Coast'!D$17 -> 29172.896 | J11: ='Central Coast'!D$18 -> 30020.423 | K11: ='Central Coast'!D$19 -> 30369.884 | L11: ='Central Coast'!D$20 -> 30826.424 | M11: ='Central Coast'!D$21 -> 31329 | O11: Central Coast | P11: 0.026024669 | Q11: -0.3056347 | R11: 0.32597978 | S11: 0.074985812 | T11: -0.027350534 | U11: =(H11-G11)/G11 -> 0.0086022545 | V11: =(I11-H11)/H11 -> 0.013728665 | W11: =(J11-I11)/I11 -> 0.02905184 | X11: =(K11-J11)/J11 -> 0.011640788 | Y11: =(L11-K11)/K11 -> 0.015032658 | Z11: =(M11-L11)/L11 -> 0.016303409
B12: Central Valley | C12: 26961.308 | D12: 23780.102 | E12: 28412.853 | F12: 26770.812 | G12: 25929.042 | H12: ='Central Valley'!D$16 -> 25640.868 | I12: ='Central Valley'!D$17 -> 25922.216 | J12: ='Central Valley'!D$18 -> 26488.492 | K12: ='Central Valley'!D$19 -> 26831.821 | L12: ='Central Valley'!D$20 -> 27203.242 | M12: ='Central Valley'!D$21 -> 27630.594 | O12: Central Valley | P12: 0.030524362 | Q12: -0.11799153 | R12: 0.19481631 | S12: -0.057792192 | T12: -0.031443586 | U12: =(H12-G12)/G12 -> -0.011113929 | V12: =(I12-H12)/H12 -> 0.010972634 | W12: =(J12-I12)/I12 -> 0.02184518 | X12: =(K12-J12)/J12 -> 0.012961459 | Y12: =(L12-K12)/K12 -> 0.013842544 | Z12: =(M12-L12)/L12 -> 0.015709612
B13: Deserts | C13: 16246.356 | D13: 11375.421 | E13: 15566.877 | F13: 17101.899 | G13: 16917.991 | H13: =Deserts!D$16 -> 16346.015 | I13: =Deserts!D$17 -> 16460.402 | J13: =Deserts!D$18 -> 16673.724 | K13: =Deserts!D$19 -> 16922.332 | L13: =Deserts!D$20 -> 17219.019 | M13: =Deserts!D$21 -> 17520.174 | O13: Deserts | P13: 0.056580751 | Q13: -0.29981708 | R13: 0.36846605 | S13: 0.098608205 | T13: -0.010753674 | U13: =(H13-G13)/G13 -> -0.033808766 | V13: =(I13-H13)/H13 -> 0.006997858 | W13: =(J13-I13)/I13 -> 0.012959711 | X13: =(K13-J13)/J13 -> 0.01491019 | Y13: =(L13-K13)/K13 -> 0.017532252 | Z13: =(M13-L13)/L13 -> 0.01748971
B14: Gold Country | C14: 15895.852 | D14: 11571.522 | E14: 14421.156 | F14: 14452.211 | G14: 14275.499 | H14: ='Gold Country'!D$16 -> 14524.607 | I14: ='Gold Country'!D$17 -> 14895.065 | J14: ='Gold Country'!D$18 -> 15139.371 | K14: ='Gold Country'!D$19 -> 15353.854 | L14: ='Gold Country'!D$20 -> 15661.09 | M14: ='Gold Country'!D$21 -> 15947.992 | O14: Gold Country | P14: 0.0089426656 | Q14: -0.27204141 | R14: 0.2462627 | S14: 0.0021534094 | T14: -0.012227276 | U14: =(H14-G14)/G14 -> 0.017450035 | V14: =(I14-H14)/H14 -> 0.025505542 | W14: =(J14-I14)/I14 -> 0.016401812 | X14: =(K14-J14)/J14 -> 0.014167184 | Y14: =(L14-K14)/K14 -> 0.020010393 | Z14: =(M14-L14)/L14 -> 0.018319386
B15: High Sierra | C15: 9468.0859 | D15: 6870.3804 | E15: 8833.3595 | F15: 9463.9479 | G15: 9456.7973 | H15: ='High Siera'!D$16 -> 9294.3205 | I15: ='High Siera'!D$17 -> 9340.0887 | J15: ='High Siera'!D$18 -> 9528.8999 | K15: ='High Siera'!D$19 -> 9654.634 | L15: ='High Siera'!D$20 -> 9825.2237 | M15: ='High Siera'!D$21 -> 9995.0872 | O15: High Sierra | P15: 0.049273042 | Q15: -0.27436439 | R15: 0.28571622 | S15: 0.071387158 | T15: -0.00075556063 | U15: =(H15-G15)/G15 -> -0.017180954 | V15: =(I15-H15)/H15 -> 0.0049243196 | W15: =(J15-I15)/I15 -> 0.020215142 | X15: =(K15-J15)/J15 -> 0.013195026 | Y15: =(L15-K15)/K15 -> 0.017669208 | Z15: =(M15-L15)/L15 -> 0.017288505
B16: Inland Empire | C16: 18612.485 | D16: 16408.932 | E16: 20288.768 | F16: 20245.917 | G16: 19812.318 | H16: ='Inland Empire'!D$16 -> 19738.098 | I16: ='Inland Empire'!D$17 -> 20078.818 | J16: ='Inland Empire'!D$18 -> 20368.256 | K16: ='Inland Empire'!D$19 -> 20586.589 | L16: ='Inland Empire'!D$20 -> 20934.087 | M16: ='Inland Empire'!D$21 -> 21272.004 | O16: Inland Empire | P16: 0.035766359 | Q16: -0.11839114 | R16: 0.23644657 | S16: -0.0021120484 | T16: -0.021416616 | U16: =(H16-G16)/G16 -> -0.0037461423 | V16: =(I16-H16)/H16 -> 0.017262061 | W16: =(J16-I16)/I16 -> 0.014415076 | X16: =(K16-J16)/J16 -> 0.010719276 | Y16: =(L16-K16)/K16 -> 0.016879849 | Z16: =(M16-L16)/L16 -> 0.016141938
B17: Los Angeles County | C17: 87207.572 | D17: 51275.353 | E17: 68984.612 | F17: 79696.971 | G17: 81973.005 | H17: ='Los Angeles'!D$16 -> 82423.294 | I17: ='Los Angeles'!D$17 -> 81538.616 | J17: ='Los Angeles'!D$18 -> 83006.606 | K17: ='Los Angeles'!D$19 -> 84048.171 | L17: ='Los Angeles'!D$20 -> 85845.597 | M17: ='Los Angeles'!D$21 -> 87177.592 | O17: Los Angeles County | P17: 0.054841205 | Q17: -0.41203096 | R17: 0.34537568 | S17: 0.1552862 | T17: 0.028558604 | U17: =(H17-G17)/G17 -> 0.0054931346 | V17: =(I17-H17)/H17 -> -0.01073334 | W17: =(J17-I17)/I17 -> 0.018003613 | X17: =(K17-J17)/J17 -> 0.01254798 | Y17: =(L17-K17)/K17 -> 0.021385666 | Z17: =(M17-L17)/L17 -> 0.015516166
B18: North Coast | C18: 5500.7115 | D18: 4604.5585 | E18: 5625.4588 | F18: 5108.5746 | G18: 4668.8343 | H18: ='North Coast'!D$16 -> 4781.5462 | I18: ='North Coast'!D$17 -> 4735.5694 | J18: ='North Coast'!D$18 -> 4870.7898 | K18: ='North Coast'!D$19 -> 4940.2592 | L18: ='North Coast'!D$20 -> 5016.9844 | M18: ='North Coast'!D$21 -> 5093.6287 | O18: North Coast | P18: -0.41709083 | Q18: -0.16291583 | R18: 0.22171515 | S18: -0.091883032 | T18: -0.086078868 | U18: =(H18-G18)/G18 -> 0.024141333 | V18: =(I18-H18)/H18 -> -0.0096154675 | W18: =(J18-I18)/I18 -> 0.028554196 | X18: =(K18-J18)/J18 -> 0.014262459 | Y18: =(L18-K18)/K18 -> 0.015530611 | Z18: =(M18-L18)/L18 -> 0.015276966
B19: Orange County | C19: 45141.361 | D19: 22478.54 | E19: 32935.692 | F19: 42427.598 | G19: 43160.169 | H19: ='Orange County'!D$16 -> 43783.753 | I19: ='Orange County'!D$17 -> 44152.017 | J19: ='Orange County'!D$18 -> 45177.352 | K19: ='Orange County'!D$19 -> 45540.1 | L19: ='Orange County'!D$20 -> 46387.796 | M19: ='Orange County'!D$21 -> 47167.381 | O19: Orange County | P19: 0.0057624373 | Q19: -0.50204116 | R19: 0.46520604 | S19: 0.28819513 | T19: 0.017266373 | U19: =(H19-G19)/G19 -> 0.014448151 | V19: =(I19-H19)/H19 -> 0.0084109541 | W19: =(J19-I19)/I19 -> 0.023222842 | X19: =(K19-J19)/J19 -> 0.0080294204 | Y19: =(L19-K19)/K19 -> 0.018614278 | Z19: =(M19-L19)/L19 -> 0.016805834
B20: Shasta Cascade | C20: 6490.1336 | D20: 5326.6412 | E20: 6482.3765 | F20: 5715.7258 | G20: 5270.2037 | H20: ='Shasta Cascade'!D$16 -> 5428.2785 | I20: ='Shasta Cascade'!D$17 -> 5475.1143 | J20: ='Shasta Cascade'!D$18 -> 5644.2945 | K20: ='Shasta Cascade'!D$19 -> 5689.7547 | L20: ='Shasta Cascade'!D$20 -> 5773.1359 | M20: ='Shasta Cascade'!D$21 -> 5854.5564 | O20: Shasta Cascade | P20: 0.07741681 | Q20: -0.17927095 | R20: 0.21697263 | S20: -0.11826692 | T20: -0.077946722 | U20: =(H20-G20)/G20 -> 0.029994058 | V20: =(I20-H20)/H20 -> 0.0086281061 | W20: =(J20-I20)/I20 -> 0.030899849 | X20: =(K20-J20)/J20 -> 0.0080541999 | Y20: =(L20-K20)/K20 -> 0.014654615 | Z20: =(M20-L20)/L20 -> 0.014103333
B21: San Diego County | C21: 49513.619 | D21: 29067.178 | E21: 39283.235 | F21: 46413.875 | G21: 47100.934 | H21: ='San Diego'!D$16 -> 47852.061 | I21: ='San Diego'!D$17 -> 47768.684 | J21: ='San Diego'!D$18 -> 49355.858 | K21: ='San Diego'!D$19 -> 49905.229 | L21: ='San Diego'!D$20 -> 50749.998 | M21: ='San Diego'!D$21 -> 51961.816 | O21: San Diego County | P21: 0.019415838 | Q21: -0.41294579 | R21: 0.35146368 | S21: 0.18151865 | T21: 0.01480288 | U21: =(H21-G21)/G21 -> 0.015947173 | V21: =(I21-H21)/H21 -> -0.0017423968 | W21: =(J21-I21)/I21 -> 0.033226242 | X21: =(K21-J21)/J21 -> 0.011130826 | Y21: =(L21-K21)/K21 -> 0.016927454 | Z21: =(M21-L21)/L21 -> 0.023878188
B22: San Francisco Bay Area | C22: 96688.561 | D22: 47800.624 | E22: 60971.03 | F22: 80613.011 | G22: 82953.568 | H22: ='San Francisco Bay Area'!D$16 -> 84026.193 | I22: ='San Francisco Bay Area'!D$17 -> 86316.538 | J22: ='San Francisco Bay Area'!D$18 -> 88200.1 | K22: ='San Francisco Bay Area'!D$19 -> 87715.039 | L22: ='San Francisco Bay Area'!D$20 -> 89090.288 | M22: ='San Francisco Bay Area'!D$21 -> 90645.895 | O22: San Francisco Bay Area | P22: 0.014807116 | Q22: -0.50562275 | R22: 0.27552791 | S22: 0.32215267 | T22: 0.029034485 | U22: =(H22-G22)/G22 -> 0.012930423 | V22: =(I22-H22)/H22 -> 0.027257521 | W22: =(J22-I22)/I22 -> 0.021821561 | X22: =(K22-J22)/J22 -> -0.0054995461 | Y22: =(L22-K22)/K22 -> 0.015678598 | Z22: =(M22-L22)/L22 -> 0.017461015
B24: Occupancy | O24: Occupancy
B25: Levels | O25: Growth
C27: 2019 | D27: 2020 | E27: 2021 | F27: 2022 | G27: 2023 | H27: 2024 | I27: 2025 | J27: 2026 | K27: 2027 | L27: 2028 | M27: 2029 | P27: 2019 | Q27: 2020 | R27: 2021 | S27: 2022 | T27: 2023 | U27: 2024 | V27: 2025 | W27: 2026 | X27: 2027 | Y27: 2028 | Z27: 2029
B29: California | C29: 0.75209223 | D29: 0.49071508 | E29: 0.6080379 | F29: 0.67389986 | G29: 0.67101193 | H29: =California!E$16 -> 0.67078661 | I29: =California!E$17 -> 0.67324806 | J29: =California!E$18 -> 0.68673588 | K29: =California!E$19 -> 0.6848903 | L29: =California!E$20 -> 0.68499258 | M29: =California!E$21 -> 0.69152085 | O29: California | P29: -0.0036554738 | Q29: -0.34753337 | R29: 0.23908541 | S29: 0.10831884 | T29: -0.0042853925 | U29: =(H29-G29)/G29 -> -0.00033579941 | V29: =(I29-H29)/H29 -> 0.0036695032 | W29: =(J29-I29)/I29 -> 0.020033947 | X29: =(K29-J29)/J29 -> -0.0026874644 | Y29: =(L29-K29)/K29 -> 0.00014934443 | Z29: =(M29-L29)/L29 -> 0.0095304221
B30: Gateway Regions* | C30: 0.7865315 | D30: 0.46693687 | E30: 0.58466231 | F30: 0.68646897 | G30: 0.69363882 | H30: 0.69899557 | I30: 0.70286563 | J30: 0.72137297 | K30: 0.72005159 | L30: 0.72386454 | M30: 0.73249581 | O30: Gateway Regions* | P30: -0.0038851649 | Q30: -0.40633417 | R30: 0.25212281 | S30: 0.174129 | T30: 0.010444534 | U30: 0.0077226783 | V30: 0.0055365907 | W30: 0.02633127 | X30: -0.0018317608 | Y30: 0.0052953845 | Z30: 0.011923883
B31: All Other Regions** | C31: 0.68696507 | D31: 0.53170784 | E31: 0.64969538 | F31: 0.65073727 | G31: 0.62907293 | H31: 0.61901433 | I31: 0.61946497 | J31: 0.6248074 | K31: 0.62256974 | L31: 0.61694258 | M31: 0.62016313 | O31: All Other Regions** | P31: -0.0021981655 | Q31: -0.22600455 | R31: 0.22190295 | S31: 0.0016036623 | T31: -0.033291995 | U31: -0.015989554 | V31: 0.00072799963 | W31: 0.0086242651 | X31: -0.003581364 | Y31: -0.0090386034 | Z31: 0.0052201747
B32: Central Coast | C32: 0.71270854 | D32: 0.4921306 | E32: 0.6445341 | F32: 0.68931032 | G32: 0.66595762 | H32: ='Central Coast'!E$16 -> 0.66836813 | I32: ='Central Coast'!E$17 -> 0.6720317 | J32: ='Central Coast'!E$18 -> 0.68159106 | K32: ='Central Coast'!E$19 -> 0.68045177 | L32: ='Central Coast'!E$20 -> 0.67930785 | M32: ='Central Coast'!E$21 -> 0.68582872 | O32: Central Coast | P32: -0.011490102 | Q32: -0.30949248 | R32: 0.309681 | S32: 0.069470679 | T32: -0.03387835 | U32: =(H32-G32)/G32 -> 0.0036196134 | V32: =(I32-H32)/H32 -> 0.0054813678 | W32: =(J32-I32)/I32 -> 0.014224559 | X32: =(K32-J32)/J32 -> -0.0016715056 | Y32: =(L32-K32)/K32 -> -0.00168113 | Z32: =(M32-L32)/L32 -> 0.009599294
B33: Central Valley | C33: 0.67808709 | D33: 0.57955603 | E33: 0.67731762 | F33: 0.63519224 | G33: 0.61700308 | H33: ='Central Valley'!E$16 -> 0.59680701 | I33: ='Central Valley'!E$17 -> 0.6019172 | J33: ='Central Valley'!E$18 -> 0.60390983 | K33: ='Central Valley'!E$19 -> 0.59768519 | L33: ='Central Valley'!E$20 -> 0.57803745 | M33: ='Central Valley'!E$21 -> 0.5829069 | O33: Central Valley | P33: 0.0018784069 | Q33: -0.14530737 | R33: 0.16868358 | S33: -0.062194423 | T33: -0.028635682 | U33: =(H33-G33)/G33 -> -0.032732521 | V33: =(I33-H33)/H33 -> 0.0085625431 | W33: =(J33-I33)/I33 -> 0.0033104761 | X33: =(K33-J33)/J33 -> -0.010307245 | Y33: =(L33-K33)/K33 -> -0.032873054 | Z33: =(M33-L33)/L33 -> 0.0084241189
B34: Deserts | C34: 0.61544667 | D34: 0.47609848 | E34: 0.56905668 | F34: 0.61546773 | G34: 0.60701477 | H34: =Deserts!E$16 -> 0.58322731 | I34: =Deserts!E$17 -> 0.58226717 | J34: =Deserts!E$18 -> 0.58285977 | K34: =Deserts!E$19 -> 0.58471257 | L34: =Deserts!E$20 -> 0.58844366 | M34: =Deserts!E$21 -> 0.59530824 | O34: Deserts | P34: -0.0049751879 | Q34: -0.22641797 | R34: 0.19524994 | S34: 0.081557871 | T34: -0.013734215 | U34: =(H34-G34)/G34 -> -0.039187604 | V34: =(I34-H34)/H34 -> -0.0016462572 | W34: =(J34-I34)/I34 -> 0.0010177514 | X34: =(K34-J34)/J34 -> 0.0031788066 | Y34: =(L34-K34)/K34 -> 0.0063810663 | Z34: =(M34-L34)/L34 -> 0.011665645
B35: Gold Country | C35: 0.76156913 | D35: 0.54540201 | E35: 0.67183993 | F35: 0.66302148 | G35: 0.64640899 | H35: ='Gold Country'!E$16 -> 0.65193431 | I35: ='Gold Country'!E$17 -> 0.65724397 | J35: ='Gold Country'!E$18 -> 0.66112837 | K35: ='Gold Country'!E$19 -> 0.66006851 | L35: ='Gold Country'!E$20 -> 0.64684377 | M35: ='Gold Country'!E$21 -> 0.65020012 | O35: Gold Country | P35: 0.013695939 | Q35: -0.28384438 | R35: 0.23182517 | S35: -0.013125819 | T35: -0.025055728 | U35: =(H35-G35)/G35 -> 0.0085477101 | V35: =(I35-H35)/H35 -> 0.0081444804 | W35: =(J35-I35)/I35 -> 0.0059101344 | X35: =(K35-J35)/J35 -> -0.0016031063 | Y35: =(L35-K35)/K35 -> -0.020035406 | Z35: =(M35-L35)/L35 -> 0.0051887975
B36: High Sierra | C36: 0.63103395 | D36: 0.47785917 | E36: 0.57669984 | F36: 0.60128325 | G36: 0.59112799 | H36: ='High Siera'!E$16 -> 0.58369189 | I36: ='High Siera'!E$17 -> 0.58898586 | J36: ='High Siera'!E$18 -> 0.59874644 | K36: ='High Siera'!E$19 -> 0.60056663 | L36: ='High Siera'!E$20 -> 0.60619033 | M36: ='High Siera'!E$21 -> 0.61513273 | O36: High Sierra | P36: 0.0042190297 | Q36: -0.2427362 | R36: 0.20684059 | S36: 0.042627751 | T36: -0.016889313 | U36: =(H36-G36)/G36 -> -0.012579517 | V36: =(I36-H36)/H36 -> 0.0090698074 | W36: =(J36-I36)/I36 -> 0.016571841 | X36: =(K36-J36)/J36 -> 0.0030399923 | Y36: =(L36-K36)/K36 -> 0.0093639916 | Z36: =(M36-L36)/L36 -> 0.014751816
B37: Inland Empire | C37: 0.71436511 | D37: 0.59986774 | E37: 0.72700272 | F37: 0.70103186 | G37: 0.6716996 | H37: ='Inland Empire'!E$16 -> 0.64844588 | I37: ='Inland Empire'!E$17 -> 0.63696109 | J37: ='Inland Empire'!E$18 -> 0.63577454 | K37: ='Inland Empire'!E$19 -> 0.62910462 | L37: ='Inland Empire'!E$20 -> 0.62442438 | M37: ='Inland Empire'!E$21 -> 0.61625299 | O37: Inland Empire | P37: -0.010285002 | Q37: -0.16027851 | R37: 0.21193835 | S37: -0.035723195 | T37: -0.041841543 | U37: =(H37-G37)/G37 -> -0.034619233 | V37: =(I37-H37)/H37 -> -0.017711247 | W37: =(J37-I37)/I37 -> -0.0018628284 | X37: =(K37-J37)/J37 -> -0.010491014 | Y37: =(L37-K37)/K37 -> -0.0074395304 | Z37: =(M37-L37)/L37 -> -0.013086267
B38: Los Angeles County | C38: 0.79195076 | D38: 0.4939707 | E38: 0.63792685 | F38: 0.70605667 | G38: 0.71689907 | H38: ='Los Angeles'!E$16 -> 0.7217188 | I38: ='Los Angeles'!E$17 -> 0.71968275 | J38: ='Los Angeles'!E$18 -> 0.73743337 | K38: ='Los Angeles'!E$19 -> 0.73951922 | L38: ='Los Angeles'!E$20 -> 0.74207606 | M38: ='Los Angeles'!E$21 -> 0.74984103 | O38: Los Angeles County | P38: -0.0064619419 | Q38: -0.37626084 | R38: 0.29142649 | S38: 0.1067988 | T38: 0.015356267 | U38: =(H38-G38)/G38 -> 0.0067230214 | V38: =(I38-H38)/H38 -> -0.0028211039 | W38: =(J38-I38)/I38 -> 0.024664503 | X38: =(K38-J38)/J38 -> 0.0028285306 | Y38: =(L38-K38)/K38 -> 0.0034574361 | Z38: =(M38-L38)/L38 -> 0.010463847
B39: North Coast | C39: 0.6568079 | D39: 0.56770473 | E39: 0.67695052 | F39: 0.59764556 | G39: 0.54369206 | H39: ='North Coast'!E$16 -> 0.55088524 | I39: ='North Coast'!E$17 -> 0.5452218 | J39: ='North Coast'!E$18 -> 0.57188471 | K39: ='North Coast'!E$19 -> 0.57709937 | L39: ='North Coast'!E$20 -> 0.58299744 | M39: ='North Coast'!E$21 -> 0.58875806 | O39: North Coast | P39: 0.0010754253 | Q39: -0.13566093 | R39: 0.19243417 | S39: -0.11715031 | T39: -0.090276741 | U39: =(H39-G39)/G39 -> 0.013230242 | V39: =(I39-H39)/H39 -> -0.010280621 | W39: =(J39-I39)/I39 -> 0.048902874 | X39: =(K39-J39)/J39 -> 0.0091183788 | Y39: =(L39-K39)/K39 -> 0.010220184 | Z39: =(M39-L39)/L39 -> 0.0098810384
B40: Orange County | C40: 0.77452795 | D40: 0.44544449 | E40: 0.57930214 | F40: 0.70660747 | G40: 0.71691207 | H40: ='Orange County'!E$16 -> 0.71785079 | I40: ='Orange County'!E$17 -> 0.72782548 | J40: ='Orange County'!E$18 -> 0.75040345 | K40: ='Orange County'!E$19 -> 0.75469466 | L40: ='Orange County'!E$20 -> 0.75974875 | M40: ='Orange County'!E$21 -> 0.76343524 | O40: Orange County | P40: -0.0013473249 | Q40: -0.42488261 | R40: 0.30050354 | S40: 0.21975637 | T40: 0.014583199 | U40: =(H40-G40)/G40 -> 0.0013093878 | V40: =(I40-H40)/H40 -> 0.01389522 | W40: =(J40-I40)/I40 -> 0.031021129 | X40: =(K40-J40)/J40 -> 0.0057185406 | Y40: =(L40-K40)/K40 -> 0.0066968648 | Z40: =(M40-L40)/L40 -> 0.0048522544
B41: Shasta Cascade | C41: 0.70351845 | D41: 0.57211118 | E41: 0.68981021 | F41: 0.60182428 | G41: 0.54995142 | H41: ='Shasta Cascade'!E$16 -> 0.55341655 | I41: ='Shasta Cascade'!E$17 -> 0.54446695 | J41: ='Shasta Cascade'!E$18 -> 0.55569348 | K41: ='Shasta Cascade'!E$19 -> 0.55317675 | L41: ='Shasta Cascade'!E$20 -> 0.55247873 | M41: ='Shasta Cascade'!E$21 -> 0.54969837 | O41: Shasta Cascade | P41: 0.051985791 | Q41: -0.18678581 | R41: 0.20572755 | S41: -0.12755093 | T41: -0.086192696 | U41: =(H41-G41)/G41 -> 0.0063007942 | V41: =(I41-H41)/H41 -> -0.016171552 | W41: =(J41-I41)/I41 -> 0.020619312 | X41: =(K41-J41)/J41 -> -0.0045289998 | Y41: =(L41-K41)/K41 -> -0.0012618258 | Z41: =(M41-L41)/L41 -> -0.0050325303
B42: San Diego County | C42: 0.78314491 | D42: 0.48791445 | E42: 0.61557434 | F42: 0.72572802 | G42: 0.73554049 | H42: ='San Diego'!E$16 -> 0.74454643 | I42: ='San Diego'!E$17 -> 0.72439538 | J42: ='San Diego'!E$18 -> 0.7360618 | K42: ='San Diego'!E$19 -> 0.73803187 | L42: ='San Diego'!E$20 -> 0.74099072 | M42: ='San Diego'!E$21 -> 0.75566159 | O42: San Diego County | P42: -0.007544588 | Q42: -0.37698062 | R42: 0.26164399 | S42: 0.17894457 | T42: 0.013520857 | U42: =(H42-G42)/G42 -> 0.012243977 | V42: =(I42-H42)/H42 -> -0.027064867 | W42: =(J42-I42)/I42 -> 0.016105053 | X42: =(K42-J42)/J42 -> 0.0026764919 | Y42: =(L42-K42)/K42 -> 0.0040091128 | Z42: =(M42-L42)/L42 -> 0.019798992
B43: San Francisco Bay Area | C43: 0.7891183 | D43: 0.43961031 | E43: 0.52117003 | F43: 0.63942422 | G43: 0.64148698 | H43: ='San Francisco Bay Area'!E$16 -> 0.64757077 | I43: ='San Francisco Bay Area'!E$17 -> 0.66555235 | J43: ='San Francisco Bay Area'!E$18 -> 0.68605531 | K43: ='San Francisco Bay Area'!E$19 -> 0.67742946 | L43: ='San Francisco Bay Area'!E$20 -> 0.68198632 | M43: ='San Francisco Bay Area'!E$21 -> 0.69044228 | O43: San Francisco Bay Area | P43: -0.0012846862 | Q43: -0.44290949 | R43: 0.18552731 | S43: 0.22690136 | T43: 0.0032259633 | U43: =(H43-G43)/G43 -> 0.0094838867 | V43: =(I43-H43)/H43 -> 0.027767751 | W43: =(J43-I43)/I43 -> 0.030805932 | X43: =(K43-J43)/J43 -> -0.01257312 | Y43: =(L43-K43)/K43 -> 0.0067266978 | Z43: =(M43-L43)/L43 -> 0.01239902
B45: Room revenue | O45: Room revenue
B46: Levels | O46: Growth
C48: 2019 | D48: 2020 | E48: 2021 | F48: 2022 | G48: 2023 | H48: 2024 | I48: 2025 | J48: 2026 | K48: 2027 | L48: 2028 | M48: 2029 | P48: 2019 | Q48: 2020 | R48: 2021 | S48: 2022 | T48: 2023 | U48: 2024 | V48: 2025 | W48: 2026 | X48: 2027 | Y48: 2028 | Z48: 2029
...

Sheet California
B1: Forecast summary: Annual, CALIFORNIA
K2: Prior forecast | R2: Current compared to prior (difference)
C3: Hotel supply (daily) | D3: Hotel room demand (daily) | E3: Occupancy | F3: ADR | G3: RevPAR | H3: Room revenue | K3: Hotel supply (daily) | L3: Hotel room demand (daily) | M3: Occupancy | N3: ADR | O3: RevPAR | P3: Room revenue | R3: Hotel supply (daily) | S3: Hotel room demand (daily) | T3: Occupancy | U3: ADR | V3: RevPAR | W3: Room revenue
B4: Levels | J4: Levels
C5: 500567.83 | D5: 265841.45 | E5: =D5/C5 -> 0.53107976 | F5: 0 | G5: =(H5/365)/C5 -> 0 | H5: =D5*F5*365 -> 0 | K5: 500567.83 | L5: 265841.45 | M5: 0.53107976 | N5: 0 | O5: 0 | P5: 0
C6: 503981.75 | D6: 366114.23 | E6: =D6/C6 -> 0.72644342 | F6: 140.09928 | G6: =(H6/365)/C6 -> 101.7742 | H6: =D6*F6*365 -> 1.8721704e+10 | K6: 503981.75 | L6: 366114.23 | M6: 0.72644342 | N6: 140.09928 | O6: 101.7742 | P6: 1.8721704e+10
C7: 506140.92 | D7: 378148.77 | E7: =D7/C7 -> 0.74712151 | F7: 149.80811 | G7: =(H7/365)/C7 -> 111.92486 | H7: =D7*F7*365 -> 2.0677159e+10 | K7: 506140.92 | L7: 378148.77 | M7: 0.74712151 | N7: 149.80811 | O7: 111.92486 | P7: 2.0677159e+10
C8: 509332.33 | D8: 383821.87 | E8: =D8/C8 -> 0.75357846 | F8: 158.35168 | G8: =(H8/365)/C8 -> 119.33042 | H8: =D8*F8*365 -> 2.2184276e+10 | K8: 509332.33 | L8: 383821.87 | M8: 0.75357846 | N8: 158.35168 | O8: 119.33042 | P8: 2.2184276e+10
C9: 515094.58 | D9: 388202.97 | E9: =D9/C9 -> 0.75365376 | F9: 161.7953 | G9: =(H9/365)/C9 -> 121.93764 | H9: =D9*F9*365 -> 2.2925437e+10 | K9: 515094.58 | L9: 388202.97 | M9: 0.75365376 | N9: 161.7953 | O9: 121.93764 | P9: 2.2925437e+10
C10: 523671.42 | D10: 395294.19 | E10: =D10/C10 -> 0.75485157 | F10: 168.10772 | G10: =(H10/365)/C10 -> 126.89638 | H10: =D10*F10*365 -> 2.4254982e+10 | K10: 523671.42 | L10: 395294.19 | M10: 0.75485157 | N10: 168.10772 | O10: 126.89638 | P10: 2.4254982e+10
B11: 2019 | C11: 541426.58 | D11: 407202.73 | E11: 0.75209223 | F11: 167.97219 | G11: 126.33058 | H11: 2.4965538e+10 | J11: 2019 | K11: 541426.58 | L11: 407202.73 | M11: 0.75209223 | N11: 167.97219 | O11: 126.33058 | P11: 2.4965538e+10
B12: 2020 | C12: 509685.92 | D12: 250110.57 | E12: 0.49071508 | F12: 131.19945 | G12: 64.381549 | H12: 1.1977245e+10 | J12: 2020 | K12: 509685.92 | L12: 250110.57 | M12: 0.49071508 | N12: 131.19945 | O12: 64.381549 | P12: 1.1977245e+10
B13: 2021 | C13: 539837.08 | D13: 328241.41 | E13: 0.6080379 | F13: 154.39565 | G13: 93.878405 | H13: 1.8497851e+10 | J13: 2021 | K13: 539837.08 | L13: 328241.41 | M13: 0.6080379 | N13: 154.39565 | O13: 93.878405 | P13: 1.8497851e+10
B14: 2022 | C14: 559898.25 | D14: 377315.35 | E14: 0.67389986 | F14: 186.17544 | G14: 125.4636 | H14: 2.56401e+10 | J14: 2022 | K14: 559898.25 | L14: 377315.35 | M14: 0.67389986 | N14: 186.17544 | O14: 125.4636 | P14: 2.56401e+10
B15: 2023 | C15: 566384.46 | D15: 380050.73 | E15: =D15/C15 -> 0.67101193 | F15: 192.36397 | G15: =(H15/365)/C15 -> 129.07852 | H15: =D15*F15*365 -> 2.6684445e+10 | J15: 2023 | K15: 566384.46 | L15: 380050.73 | M15: 0.67101193 | N15: 192.36397 | O15: 129.07852 | P15: 2.6684445e+10
B16: 2024 | C16: 570400.25 | D16: 382616.85 | E16: =D16/C16 -> 0.67078661 | F16: 188.39484 | G16: =(H16/365)/C16 -> 126.37274 | H16: =D16*F16*365 -> 2.631031e+10 | J16: 2024 | K16: 570400.25 | L16: 382616.85 | M16: 0.67078661 | N16: 188.39484 | O16: 126.37274 | P16: 2.631031e+10
B17: 2025 | C17: 573126.08 | D17: 385856.03 | E17: =D17/C17 -> 0.67324806 | F17: 190.64599 | G17: =(H17/365)/C17 -> 128.35204 | H17: =D17*F17*365 -> 2.6850095e+10 | J17: 2025 | K17: 573126.08 | L17: 385856.03 | M17: 0.67324806 | N17: 190.64599 | O17: 128.35204 | P17: 2.6850095e+10 | R17: =C17-K17 -> 0 | S17: =D17-L17 -> 0 | T17: =E17-M17 -> 0 | U17: =F17-N17 -> 0 | V17: =G17-O17 -> 0 | W17: =H17-P17 -> 0
B18: 2026 | C18: 574419.04 | D18: 394474.17 | E18: =D18/C18 -> 0.68673588 | F18: 196.17572 | G18: =(H18/365)/C18 -> 134.7209 | H18: =D18*F18*365 -> 2.8245982e+10 | J18: 2026 | K18: 579437.74 | L18: 390640.23 | M18: 0.67417118 | N18: 194.93196 | O18: 131.41751 | P18: 2.7794117e+10 | R18: =C18-K18 -> -5018.7 | S18: =D18-L18 -> 3833.9401 | T18: =E18-M18 -> 0.0125647 | U18: =F18-N18 -> 1.2437536 | V18: =G18-O18 -> 3.3033918 | W18: =H18-P18 -> 4.5186493e+08
B19: 2027 | C19: 580469.12 | D19: 397557.67 | E19: =D19/C19 -> 0.6848903 | F19: 198.15435 | G19: =(H19/365)/C19 -> 135.714 | H19: =D19*F19*365 -> 2.8753891e+10 | J19: 2027 | K19: 586413.74 | L19: 396059.24 | M19: 0.67539216 | N19: 196.50663 | O19: 132.71904 | P19: 2.8407318e+10 | R19: =C19-K19 -> -5944.625 | S19: =D19-L19 -> 1498.4253 | T19: =E19-M19 -> 0.0094981425 | U19: =F19-N19 -> 1.6477209 | V19: =G19-O19 -> 2.9949561 | W19: =H19-P19 -> 3.4657283e+08
B20: 2028 | C20: 590565.35 | D20: 404532.89 | E20: =D20/C20 -> 0.68499258 | F20: 201.37661 | G20: =(H20/365)/C20 -> 137.94149 | H20: =D20*F20*365 -> 2.9734163e+10 | J20: 2028 | K20: 591572.66 | L20: 403123.47 | M20: 0.68144372 | N20: 200.57133 | O20: 136.67807 | P20: 2.951208e+10 | R20: =C20-K20 -> -1007.3102 | S20: =D20-L20 -> 1409.4114 | T20: =E20-M20 -> 0.0035488649 | U20: =F20-N20 -> 0.8052786 | V20: =G20-O20 -> 1.2634104 | W20: =H20-P20 -> 2.2208396e+08
B21: 2029 | C21: 595203.63 | D21: 411595.72 | E21: =D21/C21 -> 0.69152085 | F21: 205.02165 | G21: =(H21/365)/C21 -> 141.77675 | H21: =D21*F21*365 -> 3.0800903e+10 | J21: 2029 | K21: 596217.33 | L21: 409921.38 | M21: 0.68753684 | N21: 204.04316 | O21: 140.28719 | P21: 3.0529204e+10 | R21: =C21-K21 -> -1013.6966 | S21: =D21-L21 -> 1674.3455 | T21: =E21-M21 -> 0.0039840133 | U21: =F21-N21 -> 0.97849017 | V21: =G21-O21 -> 1.489557 | W21: =H21-P21 -> 2.7169911e+08
B23: Growth | J23: Growth
C24: =C6/C5-1 -> 0.006820088 | D24: =D6/D5-1 -> 0.37719017 | E24: =E6/E5-1 -> 0.36786124 | F24: =F6/F5-1 -> #DIV/0! | G24: =G6/G5-1 -> #DIV/0! | H24: =H6/H5-1 -> #DIV/0!
C25: =C7/C6-1 -> 0.004284216 | D25: =D7/D6-1 -> 0.032870997 | E25: =E7/E6-1 -> 0.028464832 | F25: =F7/F6-1 -> 0.069299623 | G25: =G7/G6-1 -> 0.099737057 | H25: =H7/H6-1 -> 0.10444857
C26: =C8/C7-1 -> 0.0063053916 | D26: =D8/D7-1 -> 0.015002313 | E26: =E8/E7-1 -> 0.0086424277 | F26: =F8/F7-1 -> 0.057030136 | G26: =G8/G7-1 -> 0.066165443 | H26: =H8/H7-1 -> 0.072888033
C27: =C9/C8-1 -> 0.01131334 | D27: =D9/D8-1 -> 0.011414398 | E27: =E9/E8-1 -> 9.9927514e-05 | F27: =F9/F8-1 -> 0.021746636 | G27: =G9/G8-1 -> 0.021848737 | H27: =H9/H8-1 -> 0.033409259
C28: =C10/C9-1 -> 0.016650987 | D28: =D10/D9-1 -> 0.018266786 | E28: =E10/E9-1 -> 0.0015893348 | F28: =F10/F9-1 -> 0.039014858 | G28: =G10/G9-1 -> 0.040666201 | H28: =H10/H9-1 -> 0.05799432
B29: =B11 -> 2019 | C29: =C11/C10-1 -> 0.033905167 | D29: =D11/D10-1 -> 0.030125753 | E29: =E11/E10-1 -> -0.0036554738 | F29: =F11/F10-1 -> -0.00080619484 | G29: =G11/G10-1 -> -0.0044587216 | H29: =H11/H10-1 -> 0.029295271 | J29: 2019 | K29: =K11/K10-1 -> 0.033905167 | L29: =L11/L10-1 -> 0.030125753 | M29: =M11/M10-1 -> -0.0036554738 | N29: =N11/N10-1 -> -0.00080619484 | O29: =O11/O10-1 -> -0.0044587216 | P29: =P11/P10-1 -> 0.029295271 | R29: =C29-K29 -> 0 | S29: =D29-L29 -> 0 | T29: =E29-M29 -> 0 | U29: =F29-N29 -> 0 | V29: =G29-O29 -> 0 | W29: =H29-P29 -> 0
B30: =B12 -> 2020 | C30: =C12/C11-1 -> -0.058624138 | D30: =D12/D11-1 -> -0.38578366 | E30: =E12/E11-1 -> -0.34753337 | F30: =F12/F11-1 -> -0.21892161 | G30: =G12/G11-1 -> -0.49037241 | H30: =H12/H11-1 -> -0.52024889 | J30: 2020 | K30: =K12/K11-1 -> -0.058624138 | L30: =L12/L11-1 -> -0.38578366 | M30: =M12/M11-1 -> -0.34753337 | N30: =N12/N11-1 -> -0.21892161 | O30: =O12/O11-1 -> -0.49037241 | P30: =P12/P11-1 -> -0.52024889 | R30: =C30-K30 -> 0 | S30: =D30-L30 -> 0 | T30: =E30-M30 -> 0 | U30: =F30-N30 -> 0 | V30: =G30-O30 -> 0 | W30: =H30-P30 -> 0
B31: =B13 -> 2021 | C31: =C13/C12-1 -> 0.059156366 | D31: =D13/D12-1 -> 0.3123852 | E31: =E13/E12-1 -> 0.23908541 | F31: =F13/F12-1 -> 0.17680102 | G31: =G13/G12-1 -> 0.45815698 | H31: =H13/H12-1 -> 0.54441624 | J31: 2021 | K31: =K13/K12-1 -> 0.059156366 | L31: =L13/L12-1 -> 0.3123852 | M31: =M13/M12-1 -> 0.23908541 | N31: =N13/N12-1 -> 0.17680102 | O31: =O13/O12-1 -> 0.45815698 | P31: =P13/P12-1 -> 0.54441624 | R31: =C31-K31 -> 0 | S31: =D31-L31 -> 0 | T31: =E31-M31 -> 0 | U31: =F31-N31 -> 0 | V31: =G31-O31 -> 0 | W31: =H31-P31 -> 0
B32: =B14 -> 2022 | C32: =C14/C13-1 -> 0.03716152 | D32: =D14/D13-1 -> 0.14950565 | E32: =E14/E13-1 -> 0.10831884 | F32: =F14/F13-1 -> 0.20583346 | G32: =G14/G13-1 -> 0.33644794 | H32: =H14/H13-1 -> 0.38611238 | J32: 2022 | K32: =K14/K13-1 -> 0.03716152 | L32: =L14/L13-1 -> 0.14950565 | M32: =M14/M13-1 -> 0.10831884 | N32: =N14/N13-1 -> 0.20583346 | O32: =O14/O13-1 -> 0.33644794 | P32: =P14/P13-1 -> 0.38611238 | R32: =C32-K32 -> 0 | S32: =D32-L32 -> 0 | T32: =E32-M32 -> 0 | U32: =F32-N32 -> 0 | V32: =G32-O32 -> 0 | W32: =H32-P32 -> 0
B33: 2023 | C33: =C15/C14-1 -> 0.011584627 | D33: =D15/D14-1 -> 0.0072495898 | E33: =E15/E14-1 -> -0.0042853925 | F33: =F15/F14-1 -> 0.033240345 | G33: =G15/G14-1 -> 0.028812504 | H33: =H15/H14-1 -> 0.040730913 | J33: 2023 | K33: =K15/K14-1 -> 0.011584627 | L33: =L15/L14-1 -> 0.0072495898 | M33: =M15/M14-1 -> -0.0042853925 | N33: =N15/N14-1 -> 0.033240345 | O33: =O15/O14-1 -> 0.028812504 | P33: =P15/P14-1 -> 0.040730913 | R33: =C33-K33 -> 0 | S33: =D33-L33 -> 0 | T33: =E33-M33 -> 0 | U33: =F33-N33 -> 0 | V33: =G33-O33 -> 0 | W33: =H33-P33 -> 0
B34: 2024 | C34: =C16/C15-1 -> 0.007090215 | D34: =D16/D15-1 -> 0.0067520347 | E34: =E16/E15-1 -> -0.00033579941 | F34: =F16/F15-1 -> -0.020633423 | G34: =G16/G15-1 -> -0.020962294 | H34: =H16/H15-1 -> -0.014020706 | J34: 2024 | K34: =K16/K15-1 -> 0.007090215 | L34: =L16/L15-1 -> 0.0067520347 | M34: =M16/M15-1 -> -0.00033579941 | N34: =N16/N15-1 -> -0.020633423 | O34: =O16/O15-1 -> -0.020962294 | P34: =P16/P15-1 -> -0.014020706 | R34: =C34-K34 -> 0 | S34: =D34-L34 -> 0 | T34: =E34-M34 -> 0 | U34: =F34-N34 -> 0 | V34: =G34-O34 -> 0 | W34: =H34-P34 -> 0
B35: 2025 | C35: =C17/C16-1 -> 0.0047788081 | D35: =D17/D16-1 -> 0.0084658471 | E35: =E17/E16-1 -> 0.0036695032 | F35: =F17/F16-1 -> 0.011949067 | G35: =G17/G16-1 -> 0.015662417 | H35: =H17/H16-1 -> 0.020516073 | J35: 2025 | K35: =K17/K16-1 -> 0.0047788081 | L35: =L17/L16-1 -> 0.0084658471 | M35: =M17/M16-1 -> 0.0036695032 | N35: =N17/N16-1 -> 0.011949067 | O35: =O17/O16-1 -> 0.015662417 | P35: =P17/P16-1 -> 0.020516073 | R35: =C35-K35 -> 0 | S35: =D35-L35 -> 0 | T35: =E35-M35 -> 0 | U35: =F35-N35 -> 0 | V35: =G35-O35 -> 0 | W35: =H35-P35 -> 0
B36: 2026 | C36: =C18/C17-1 -> 0.0022559754 | D36: =D18/D17-1 -> 0.022335118 | E36: =E18/E17-1 -> 0.020033947 | F36: =F18/F17-1 -> 0.029005217 | G36: =G18/G17-1 -> 0.049620252 | H36: =H18/H17-1 -> 0.05198817 | J36: 2026 | K36: =K18/K17-1 -> 0.011012687 | L36: =L18/L17-1 -> 0.012398925 | M36: =M18/M17-1 -> 0.0013711376 | N36: =N18/N17-1 -> 0.022481326 | O36: =O18/O17-1 -> 0.023883289 | P36: =P18/P17-1 -> 0.035158995 | R36: =C36-K36 -> -0.0087567119 | S36: =D36-L36 -> 0.0099361934 | T36: =E36-M36 -> 0.018662809 | U36: =F36-N36 -> 0.0065238907 | V36: =G36-O36 -> 0.025736964 | W36: =H36-P36 -> 0.016829175
B37: 2027 | C37: =C19/C18-1 -> 0.010532511 | D37: =D19/D18-1 -> 0.0078167411 | E37: =E19/E18-1 -> -0.0026874644 | F37: =F19/F18-1 -> 0.010086056 | G37: =G19/G18-1 -> 0.0073714852 | H37: =H19/H18-1 -> 0.017981637 | J37: 2027 | K37: =K19/K18-1 -> 0.012039257 | L37: =L19/L18-1 -> 0.013872143 | M37: =M19/M18-1 -> 0.001811082 | N37: =N19/N18-1 -> 0.0080780587 | O37: =O19/O18-1 -> 0.0099037708 | P37: =P19/P18-1 -> 0.022062262 | R37: =C37-K37 -> -0.001506746 | S37: =D37-L37 -> -0.0060554023 | T37: =E37-M37 -> -0.0044985464 | U37: =F37-N37 -> 0.0020079968 | V37: =G37-O37 -> -0.0025322856 | W37: =H37-P37 -> -0.0040806254
B38: 2028 | C38: =C20/C19-1 -> 0.017393231 | D38: =D20/D19-1 -> 0.017545173 | E38: =E20/E19-1 -> 0.00014934443 | F38: =F20/F19-1 -> 0.016261344 | G38: =G20/G19-1 -> 0.016413117 | H38: =H20/H19-1 -> 0.034091825 | J38: 2028 | K38: =K20/K19-1 -> 0.0087974044 | L38: =L20/L19-1 -> 0.017836302 | M38: =M20/M19-1 -> 0.0089600718 | N38: =N20/N19-1 -> 0.02068479 | O38: =O20/O19-1 -> 0.029830199 | P38: =P20/P19-1 -> 0.038890031 | R38: =C38-K38 -> 0.008595827 | S38: =D38-L38 -> -0.00029112815 | T38: =E38-M38 -> -0.0088107274 | U38: =F38-N38 -> -0.0044234459 | V38: =G38-O38 -> -0.013417082 | W38: =H38-P38 -> -0.0047982061
B39: 2029 | C39: =C21/C20-1 -> 0.0078539627 | D39: =D21/D20-1 -> 0.017459236 | E39: =E21/E20-1 -> 0.0095304221 | F39: =F21/F20-1 -> 0.018100623 | G39: =G21/G20-1 -> 0.027803552 | H39: =H21/H20-1 -> 0.035875883 | J39: 2029 | K39: =K21/K20-1 -> 0.0078513849 | L39: =L21/L20-1 -> 0.016863075 | M39: =M21/M20-1 -> 0.0089414868 | N39: =N21/N20-1 -> 0.017309705 | O39: =O21/O20-1 -> 0.026405966 | P39: =P21/P20-1 -> 0.034464675 | R39: =C39-K39 -> 2.5778146e-06 | S39: =D39-L39 -> 0.00059616169 | T39: =E39-M39 -> 0.00058893535 | U39: =F39-N39 -> 0.00079091822 | V39: =G39-O39 -> 0.0013975857 | W39: =H39-P39 -> 0.0014112081
B41: Source: CoStar; Tourism Economics

Sheet Gateway
B1: ="Forecast summary: Annual, Gateway Regions*" -> Forecast summary: Annual, Gateway Regions*
K2: Prior forecast | R2: Current compared to prior (difference)
C3: Hotel supply (daily) | D3: Hotel room demand (daily) | E3: Occupancy | F3: ADR | G3: RevPAR | H3: Room revenue | K3: Hotel supply (daily) | L3: Hotel room demand (daily) | M3: Occupancy | N3: ADR | O3: RevPAR | P3: Room revenue | R3: Hotel supply (daily) | S3: Hotel room demand (daily) | T3: Occupancy | U3: ADR | V3: RevPAR | W3: Room revenue
B4: Levels | J4: Levels
C5: =SUM('Los Angeles'!C5,'Orange County'!C5,'San Diego'!C5,'San Francisco Bay Area'!C5) -> 325856.59 | D5: =SUM('Los Angeles'!D5,'Orange County'!D5,'San Diego'!D5,'San Francisco Bay Area'!D5) -> 158764.74 | E5: =D5/C5 -> 0.48722273 | F5: =H5/(D5*365) -> #DIV/0! | G5: =(H5/365)/C5 -> #DIV/0! | H5: =SUM('Los Angeles'!H5,'Orange County'!H5,'San Diego'!H5,'San Francisco Bay Area'!H5) -> #DIV/0! | K5: 325856.59 | L5: 158764.74 | M5: 0.48722273 | N5: #DIV/0! | O5: #DIV/0! | P5: #DIV/0!
C6: =SUM('Los Angeles'!C6,'Orange County'!C6,'San Diego'!C6,'San Francisco Bay Area'!C6) -> 328224.25 | D6: =SUM('Los Angeles'!D6,'Orange County'!D6,'San Diego'!D6,'San Francisco Bay Area'!D6) -> 255051.62 | E6: =D6/C6 -> 0.77706514 | F6: =H6/(D6*365) -> 154.30148 | G6: =(H6/365)/C6 -> 119.9023 | H6: =SUM('Los Angeles'!H6,'Orange County'!H6,'San Diego'!H6,'San Francisco Bay Area'!H6) -> 1.4364517e+10 | K6: 328224.25 | L6: 255051.62 | M6: 0.77706514 | N6: 154.30148 | O6: 119.9023 | P6: 1.4364517e+10
C7: =SUM('Los Angeles'!C7,'Orange County'!C7,'San Diego'!C7,'San Francisco Bay Area'!C7) -> 330151.25 | D7: =SUM('Los Angeles'!D7,'Orange County'!D7,'San Diego'!D7,'San Francisco Bay Area'!D7) -> 261461.16 | E7: =D7/C7 -> 0.79194357 | F7: =H7/(D7*365) -> 166.22049 | G7: =(H7/365)/C7 -> 131.63725 | H7: =SUM('Los Angeles'!H7,'Orange County'!H7,'San Diego'!H7,'San Francisco Bay Area'!H7) -> 1.5862974e+10 | K7: 330151.25 | L7: 261461.16 | M7: 0.79194357 | N7: 166.22049 | O7: 131.63725 | P7: 1.5862974e+10
C8: =SUM('Los Angeles'!C8,'Orange County'!C8,'San Diego'!C8,'San Francisco Bay Area'!C8) -> 332995.17 | D8: =SUM('Los Angeles'!D8,'Orange County'!D8,'San Diego'!D8,'San Francisco Bay Area'!D8) -> 264686.39 | E8: =D8/C8 -> 0.79486557 | F8: =H8/(D8*365) -> 175.78716 | G8: =(H8/365)/C8 -> 139.72716 | H8: =SUM('Los Angeles'!H8,'Orange County'!H8,'San Diego'!H8,'San Francisco Bay Area'!H8) -> 1.6982891e+10 | K8: 332995.17 | L8: 264686.39 | M8: 0.79486557 | N8: 175.78716 | O8: 139.72716 | P8: 1.6982891e+10
C9: =SUM('Los Angeles'!C9,'Orange County'!C9,'San Diego'!C9,'San Francisco Bay Area'!C9) -> 337962.75 | D9: =SUM('Los Angeles'!D9,'Orange County'!D9,'San Diego'!D9,'San Francisco Bay Area'!D9) -> 266779.16 | E9: =D9/C9 -> 0.78937444 | F9: =H9/(D9*365) -> 179.09453 | G9: =(H9/365)/C9 -> 141.37265 | H9: =SUM('Los Angeles'!H9,'Orange County'!H9,'San Diego'!H9,'San Francisco Bay Area'!H9) -> 1.7439221e+10 | K9: 337962.75 | L9: 266779.16 | M9: 0.78937444 | N9: 179.09453 | O9: 141.37265 | P9: 1.7439221e+10
C10: =SUM('Los Angeles'!C10,'Orange County'!C10,'San Diego'!C10,'San Francisco Bay Area'!C10) -> 343724.67 | D10: =SUM('Los Angeles'!D10,'Orange County'!D10,'San Diego'!D10,'San Francisco Bay Area'!D10) -> 271404.73 | E10: =D10/C10 -> 0.78959922 | F10: =H10/(D10*365) -> 186.17152 | G10: =(H10/365)/C10 -> 147.00089 | H10: =SUM('Los Angeles'!H10,'Orange County'!H10,'San Diego'!H10,'San Francisco Bay Area'!H10) -> 1.8442659e+10 | K10: 343724.67 | L10: 271404.73 | M10: 0.78959922 | N10: 186.17152 | O10: 147.00089 | P10: 1.8442659e+10
B11: 2019 | C11: =SUM('Los Angeles'!C11,'Orange County'!C11,'San Diego'!C11,'San Francisco Bay Area'!C11) -> 354151.25 | D11: =SUM('Los Angeles'!D11,'Orange County'!D11,'San Diego'!D11,'San Francisco Bay Area'!D11) -> 278551.11 | E11: =D11/C11 -> 0.7865315 | F11: =H11/(D11*365) -> 185.86269 | G11: =(H11/365)/C11 -> 146.18686 | H11: =SUM('Los Angeles'!H11,'Orange County'!H11,'San Diego'!H11,'San Francisco Bay Area'!H11) -> 1.8896874e+10 | J11: 2019 | K11: 354151.25 | L11: 278551.11 | M11: 0.7865315 | N11: 185.86269 | O11: 146.18686 | P11: 1.8896874e+10
B12: 2020 | C12: =SUM('Los Angeles'!C12,'Orange County'!C12,'San Diego'!C12,'San Francisco Bay Area'!C12) -> 322574 | D12: =SUM('Los Angeles'!D12,'Orange County'!D12,'San Diego'!D12,'San Francisco Bay Area'!D12) -> 150621.69 | E12: =D12/C12 -> 0.46693687 | F12: =H12/(D12*365) -> 140.32627 | G12: =(H12/365)/C12 -> 65.523511 | H12: =SUM('Los Angeles'!H12,'Orange County'!H12,'San Diego'!H12,'San Francisco Bay Area'!H12) -> 7.7147061e+09 | J12: 2020 | K12: 322574 | L12: 150621.69 | M12: 0.46693687 | N12: 140.32627 | O12: 65.523511 | P12: 7.7147061e+09
B13: 2021 | C13: =SUM('Los Angeles'!C13,'Orange County'!C13,'San Diego'!C13,'San Francisco Bay Area'!C13) -> 345797.17 | D13: =SUM('Los Angeles'!D13,'Orange County'!D13,'San Diego'!D13,'San Francisco Bay Area'!D13) -> 202174.57 | E13: =D13/C13 -> 0.58466231 | F13: =H13/(D13*365) -> 159.86598 | G13: =(H13/365)/C13 -> 93.467615 | H13: =SUM('Los Angeles'!H13,'Orange County'!H13,'San Diego'!H13,'San Francisco Bay Area'!H13) -> 1.1797105e+10 | J13: 2021 | K13: 345797.17 | L13: 202174.57 | M13: 0.58466231 | N13: 159.86598 | O13: 93.467615 | P13: 1.1797105e+10
B14: 2022 | C14: =SUM('Los Angeles'!C14,'Orange County'!C14,'San Diego'!C14,'San Francisco Bay Area'!C14) -> 362946.42 | D14: =SUM('Los Angeles'!D14,'Orange County'!D14,'San Diego'!D14,'San Francisco Bay Area'!D14) -> 249151.45 | E14: =D14/C14 -> 0.68646897 | F14: =H14/(D14*365) -> 197.94388 | G14: =(H14/365)/C14 -> 135.88233 | H14: =SUM('Los Angeles'!H14,'Orange County'!H14,'San Diego'!H14,'San Francisco Bay Area'!H14) -> 1.8001072e+10 | J14: 2022 | K14: 362946.42 | L14: 249151.45 | M14: 0.68646897 | N14: 197.94388 | O14: 135.88233 | P14: 1.8001072e+10
B15: 2023 | C15: =SUM('Los Angeles'!C15,'Orange County'!C15,'San Diego'!C15,'San Francisco Bay Area'!C15) -> 367897.05 | D15: =SUM('Los Angeles'!D15,'Orange County'!D15,'San Diego'!D15,'San Francisco Bay Area'!D15) -> 255187.68 | E15: =D15/C15 -> 0.69363882 | F15: =H15/(D15*365) -> 206.39232 | G15: =(H15/365)/C15 -> 143.16173 | H15: =SUM('Los Angeles'!H15,'Orange County'!H15,'San Diego'!H15,'San Francisco Bay Area'!H15) -> 1.9224104e+10 | J15: 2023 | K15: 367897.05 | L15: 255187.68 | M15: 0.69363882 | N15: 206.39232 | O15: 143.16173 | P15: 1.9224104e+10
B16: 2024 | C16: =SUM('Los Angeles'!C16,'Orange County'!C16,'San Diego'!C16,'San Francisco Bay Area'!C16) -> 369223.08 | D16: =SUM('Los Angeles'!D16,'Orange County'!D16,'San Diego'!D16,'San Francisco Bay Area'!D16) -> 258085.3 | E16: =D16/C16 -> 0.69899557 | F16: =H16/(D16*365) -> 200.39062 | G16: =(H16/365)/C16 -> 140.07216 | H16: =SUM('Los Angeles'!H16,'Orange County'!H16,'San Diego'!H16,'San Francisco Bay Area'!H16) -> 1.8877024e+10 | J16: 2024 | K16: 369223.08 | L16: 258085.3 | M16: 0.69899557 | N16: 200.39062 | O16: 140.07216 | P16: 1.8877024e+10
B17: 2025 | C17: =SUM('Los Angeles'!C17,'Orange County'!C17,'San Diego'!C17,'San Francisco Bay Area'!C17) -> 369595.33 | D17: =SUM('Los Angeles'!D17,'Orange County'!D17,'San Diego'!D17,'San Francisco Bay Area'!D17) -> 259775.85 | E17: =D17/C17 -> 0.70286563 | F17: =H17/(D17*365) -> 203.35707 | G17: =(H17/365)/C17 -> 142.93269 | H17: =SUM('Los Angeles'!H17,'Orange County'!H17,'San Diego'!H17,'San Francisco Bay Area'!H17) -> 1.9281949e+10 | J17: 2025 | K17: 369595.33 | L17: 259775.85 | M17: 0.70286563 | N17: 203.35707 | O17: 142.93269 | P17: 1.9281949e+10 | R17: =C17-K17 -> 0 | S17: =D17-L17 -> 0 | T17: =E17-M17 -> 0 | U17: =F17-N17 -> 0 | V17: =G17-O17 -> 0 | W17: =H17-P17 -> 0
B18: 2026 | C18: =SUM('Los Angeles'!C18,'Orange County'!C18,'San Diego'!C18,'San Francisco Bay Area'!C18) -> 368380.75 | D18: =SUM('Los Angeles'!D18,'Orange County'!D18,'San Diego'!D18,'San Francisco Bay Area'!D18) -> 265739.92 | E18: =D18/C18 -> 0.72137297 | F18: =H18/(D18*365) -> 210.16873 | G18: =(H18/365)/C18 -> 151.61004 | H18: =SUM('Los Angeles'!H18,'Orange County'!H18,'San Diego'!H18,'San Francisco Bay Area'!H18) -> 2.0385331e+10 | J18: 2026 | K18: 371738.24 | L18: 263144.08 | M18: 0.70787465 | N18: 208.90189 | O18: 147.87635 | P18: 2.0064523e+10 | R18: =C18-K18 -> -3357.4917 | S18: =D18-L18 -> 2595.8383 | T18: =E18-M18 -> 0.013498321 | U18: =F18-N18 -> 1.2668416 | V18: =G18-O18 -> 3.73369 | W18: =H18-P18 -> 3.2080795e+08
B19: 2027 | C19: =SUM('Los Angeles'!C19,'Orange County'!C19,'San Diego'!C19,'San Francisco Bay Area'!C19) -> 371096.38 | D19: =SUM('Los Angeles'!D19,'Orange County'!D19,'San Diego'!D19,'San Francisco Bay Area'!D19) -> 267208.54 | E19: =D19/C19 -> 0.72005159 | F19: =H19/(D19*365) -> 212.28707 | G19: =(H19/365)/C19 -> 152.85764 | H19: =SUM('Los Angeles'!H19,'Orange County'!H19,'San Diego'!H19,'San Francisco Bay Area'!H19) -> 2.0704595e+10 | J19: 2027 | K19: 375567.92 | L19: 266361.36 | M19: 0.70922289 | N19: 210.27865 | O19: 149.13443 | P19: 2.0443689e+10 | R19: =C19-K19 -> -4471.5333 | S19: =D19-L19 -> 847.17684 | T19: =E19-M19 -> 0.010828698 | U19: =F19-N19 -> 2.0084174 | V19: =G19-O19 -> 3.7232081 | W19: =H19-P19 -> 2.6090546e+08
B20: 2028 | C20: =SUM('Los Angeles'!C20,'Orange County'!C20,'San Diego'!C20,'San Francisco Bay Area'!C20) -> 375862.7 | D20: =SUM('Los Angeles'!D20,'Orange County'!D20,'San Diego'!D20,'San Francisco Bay Area'!D20) -> 272073.68 | E20: =D20/C20 -> 0.72386454 | F20: =H20/(D20*365) -> 215.6811 | G20: =(H20/365)/C20 -> 156.1239 | H20: =SUM('Los Angeles'!H20,'Orange County'!H20,'San Diego'!H20,'San Francisco Bay Area'!H20) -> 2.141862e+10 | J20: 2028 | K20: 377950.44 | L20: 271108.39 | M20: 0.71731201 | N20: 214.94526 | O20: 154.18282 | P20: 2.1269814e+10 | R20: =C20-K20 -> -2087.7371 | S20: =D20-L20 -> 965.29258 | T20: =E20-M20 -> 0.0065525296 | U20: =F20-N20 -> 0.73583696 | V20: =G20-O20 -> 1.9410815 | W20: =H20-P20 -> 1.4880573e+08
B21: 2029 | C21: =SUM('Los Angeles'!C21,'Orange County'!C21,'San Diego'!C21,'San Francisco Bay Area'!C21) -> 378094.56 | D21: =SUM('Los Angeles'!D21,'Orange County'!D21,'San Diego'!D21,'San Francisco Bay Area'!D21) -> 276952.68 | E21: =D21/C21 -> 0.73249581 | F21: =H21/(D21*365) -> 219.68223 | G21: =(H21/365)/C21 -> 160.91632 | H21: =SUM('Los Angeles'!H21,'Orange County'!H21,'San Diego'!H21,'San Francisco Bay Area'!H21) -> 2.2207178e+10 | J21: 2029 | K21: 380197.73 | L21: 275776.49 | M21: 0.72535016 | N21: 218.65025 | O21: 158.59799 | P21: 2.2008988e+10 | R21: =C21-K21 -> -2103.1688 | S21: =D21-L21 -> 1176.1987 | T21: =E21-M21 -> 0.007145653 | U21: =F21-N21 -> 1.031982 | V21: =G21-O21 -> 2.3183213 | W21: =H21-P21 -> 1.9819001e+08
B23: Growth | J23: Growth
B29: =B11 -> 2019 | C29: =C11/C10-1 -> 0.030334114 | D29: =D11/D10-1 -> 0.026331096 | E29: =E11/E10-1 -> -0.0038851649 | F29: =F11/F10-1 -> -0.0016588779 | G29: =G11/G10-1 -> -0.0055375977 | H29: =H11/H10-1 -> 0.024628538 | J29: 2019 | K29: =K11/K10-1 -> 0.030334114 | L29: =L11/L10-1 -> 0.026331096 | M29: =M11/M10-1 -> -0.0038851649 | N29: =N11/N10-1 -> -0.0016588779 | O29: =O11/O10-1 -> -0.0055375977 | P29: =P11/P10-1 -> 0.024628538 | R29: =C29-K29 -> 0 | S29: =D29-L29 -> 0 | T29: =E29-M29 -> 0 | U29: =F29-N29 -> 0 | V29: =G29-O29 -> 0 | W29: =H29-P29 -> 0
B30: =B12 -> 2020 | C30: =C12/C11-1 -> -0.089163175 | D30: =D12/D11-1 -> -0.4592673 | E30: =E12/E11-1 -> -0.40633417 | F30: =F12/F11-1 -> -0.24500031 | G30: =G12/G11-1 -> -0.55178248 | H30: =H12/H11-1 -> -0.59174698 | J30: 2020 | K30: =K12/K11-1 -> -0.089163175 | L30: =L12/L11-1 -> -0.4592673 | M30: =M12/M11-1 -> -0.40633417 | N30: =N12/N11-1 -> -0.24500031 | O30: =O12/O11-1 -> -0.55178248 | P30: =P12/P11-1 -> -0.59174698 | R30: =C30-K30 -> 0 | S30: =D30-L30 -> 0 | T30: =E30-M30 -> 0 | U30: =F30-N30 -> 0 | V30: =G30-O30 -> 0 | W30: =H30-P30 -> 0
B31: =B13 -> 2021 | C31: =C13/C12-1 -> 0.0719933 | D31: =D13/D12-1 -> 0.34226726 | E31: =E13/E12-1 -> 0.25212281 | F31: =F13/F12-1 -> 0.13924485 | G31: =G13/G12-1 -> 0.42647446 | H31: =H13/H12-1 -> 0.52917106 | J31: 2021 | K31: =K13/K12-1 -> 0.0719933 | L31: =L13/L12-1 -> 0.34226726 | M31: =M13/M12-1 -> 0.25212281 | N31: =N13/N12-1 -> 0.13924485 | O31: =O13/O12-1 -> 0.42647446 | P31: =P13/P12-1 -> 0.52917106 | R31: =C31-K31 -> 0 | S31: =D31-L31 -> 0 | T31: =E31-M31 -> 0 | U31: =F31-N31 -> 0 | V31: =G31-O31 -> 0 | W31: =H31-P31 -> 0
B32: =B14 -> 2022 | C32: =C14/C13-1 -> 0.049593379 | D32: =D14/D13-1 -> 0.23235803 | E32: =E14/E13-1 -> 0.174129 | F32: =F14/F13-1 -> 0.23818637 | G32: =G14/G13-1 -> 0.45379053 | H32: =H14/H13-1 -> 0.52588891 | J32: 2022 | K32: =K14/K13-1 -> 0.049593379 | L32: =L14/L13-1 -> 0.23235803 | M32: =M14/M13-1 -> 0.174129 | N32: =N14/N13-1 -> 0.23818637 | O32: =O14/O13-1 -> 0.45379053 | P32: =P14/P13-1 -> 0.52588891 | R32: =C32-K32 -> 0 | S32: =D32-L32 -> 0 | T32: =E32-M32 -> 0 | U32: =F32-N32 -> 0 | V32: =G32-O32 -> 0 | W32: =H32-P32 -> 0
B33: 2023 | C33: =C15/C14-1 -> 0.013640117 | D33: =D15/D14-1 -> 0.024227116 | E33: =E15/E14-1 -> 0.010444534 | F33: =F15/F14-1 -> 0.042680998 | G33: =G15/G14-1 -> 0.053571316 | H33: =H15/H14-1 -> 0.067942152 | J33: 2023 | K33: =K15/K14-1 -> 0.013640117 | L33: =L15/L14-1 -> 0.024227116 | M33: =M15/M14-1 -> 0.010444534 | N33: =N15/N14-1 -> 0.042680998 | O33: =O15/O14-1 -> 0.053571316 | P33: =P15/P14-1 -> 0.067942152 | R33: =C33-K33 -> 0 | S33: =D33-L33 -> 0 | T33: =E33-M33 -> 0 | U33: =F33-N33 -> 0 | V33: =G33-O33 -> 0 | W33: =H33-P33 -> 0
B34: 2024 | C34: =C16/C15-1 -> 0.0036043642 | D34: =D16/D15-1 -> 0.011354878 | E34: =E16/E15-1 -> 0.0077226783 | F34: =F16/F15-1 -> -0.029079088 | G34: =G16/G15-1 -> -0.021580978 | H34: =H16/H15-1 -> -0.018054399 | J34: 2024 | K34: =K16/K15-1 -> 0.0036043642 | L34: =L16/L15-1 -> 0.011354878 | M34: =M16/M15-1 -> 0.0077226783 | N34: =N16/N15-1 -> -0.029079088 | O34: =O16/O15-1 -> -0.021580978 | P34: =P16/P15-1 -> -0.018054399 | R34: =C34-K34 -> 0 | S34: =D34-L34 -> 0 | T34: =E34-M34 -> 0 | U34: =F34-N34 -> 0 | V34: =G34-O34 -> 0 | W34: =H34-P34 -> 0
B35: 2025 | C35: =C17/C16-1 -> 0.0010081981 | D35: =D17/D16-1 -> 0.0065503707 | E35: =E17/E16-1 -> 0.0055365907 | F35: =F17/F16-1 -> 0.014803317 | G35: =G17/G16-1 -> 0.020421867 | H35: =H17/H16-1 -> 0.021450655 | J35: 2025 | K35: =K17/K16-1 -> 0.0010081981 | L35: =L17/L16-1 -> 0.0065503707 | M35: =M17/M16-1 -> 0.0055365907 | N35: =N17/N16-1 -> 0.014803317 | O35: =O17/O16-1 -> 0.020421867 | P35: =P17/P16-1 -> 0.021450655 | R35: =C35-K35 -> 0 | S35: =D35-L35 -> 0 | T35: =E35-M35 -> 0 | U35: =F35-N35 -> 0 | V35: =G35-O35 -> 0 | W35: =H35-P35 -> 0
B36: 2026 | C36: =C18/C17-1 -> -0.0032862518 | D36: =D18/D17-1 -> 0.022958487 | E36: =E18/E17-1 -> 0.02633127 | F36: =F18/F17-1 -> 0.033496086 | G36: =G18/G17-1 -> 0.06070935 | H36: =H18/H17-1 -> 0.057223592 | J36: 2026 | K36: =K18/K17-1 -> 0.0057979854 | L36: =L18/L17-1 -> 0.012965879 | M36: =M18/M17-1 -> 0.0071265735 | N36: =N18/N17-1 -> 0.027266445 | O36: =O18/O17-1 -> 0.034587335 | P36: =P18/P17-1 -> 0.040585857 | R36: =C36-K36 -> -0.0090842372 | S36: =D36-L36 -> 0.009992608 | T36: =E36-M36 -> 0.019204696 | U36: =F36-N36 -> 0.0062296412 | V36: =G36-O36 -> 0.026122015 | W36: =H36-P36 -> 0.016637735
B37: 2027 | C37: =C19/C18-1 -> 0.0073718112 | D37: =D19/D18-1 -> 0.005526547 | E37: =E19/E18-1 -> -0.0018317608 | F37: =F19/F18-1 -> 0.010079196 | G37: =G19/G18-1 -> 0.0082289729 | H37: =H19/H18-1 -> 0.015661447 | J37: 2027 | K37: =K19/K18-1 -> 0.010302074 | L37: =L19/L18-1 -> 0.012226327 | M37: =M19/M18-1 -> 0.0019046312 | N37: =N19/N18-1 -> 0.0065904436 | O37: =O19/O18-1 -> 0.0085076271 | P37: =P19/P18-1 -> 0.018897348 | R37: =C37-K37 -> -0.0029302632 | S37: =D37-L37 -> -0.0066997802 | T37: =E37-M37 -> -0.003736392 | U37: =F37-N37 -> 0.0034887528 | V37: =G37-O37 -> -0.00027865421 | W37: =H37-P37 -> -0.0032359011
B38: 2028 | C38: =C20/C19-1 -> 0.012843878 | D38: =D20/D19-1 -> 0.018207276 | E38: =E20/E19-1 -> 0.0052953845 | F38: =F20/F19-1 -> 0.015987928 | G38: =G20/G19-1 -> 0.021367974 | H38: =H20/H19-1 -> 0.0344863 | J38: 2028 | K38: =K20/K19-1 -> 0.0063437805 | L38: =L20/L19-1 -> 0.017821743 | M38: =M20/M19-1 -> 0.011405608 | N38: =N20/N19-1 -> 0.022192508 | O38: =O20/O19-1 -> 0.033851236 | P38: =P20/P19-1 -> 0.040409761 | R38: =C38-K38 -> 0.0065000975 | S38: =D38-L38 -> 0.00038553248 | T38: =E38-M38 -> -0.0061102236 | U38: =F38-N38 -> -0.0062045807 | V38: =G38-O38 -> -0.012483261 | W38: =H38-P38 -> -0.0059234608
B39: 2029 | C39: =C21/C20-1 -> 0.0059379738 | D39: =D21/D20-1 -> 0.017932661 | E39: =E21/E20-1 -> 0.011923883 | F39: =F21/F20-1 -> 0.018551171 | G39: =G21/G20-1 -> 0.030696257 | H39: =H21/H20-1 -> 0.036816504 | J39: 2029 | K39: =K21/K20-1 -> 0.0059460032 | L39: =L21/L20-1 -> 0.01721857 | M39: =M21/M20-1 -> 0.011205937 | N39: =N21/N20-1 -> 0.017236909 | O39: =O21/O20-1 -> 0.028636002 | P39: =P21/P20-1 -> 0.034752275 | R39: =C39-K39 -> -8.0294675e-06 | S39: =D39-L39 -> 0.0007140904 | T39: =E39-M39 -> 0.0007179467 | U39: =F39-N39 -> 0.001314262 | V39: =G39-O39 -> 0.002060255 | W39: =H39-P39 -> 0.0020642294
B41: Source: CoStar; Tourism Economics
B42: *Gateway Regions: Los Angeles, Orange County, San Diego, San Francisco Bay Area

Sheet All Other Regions
B1: ="Forecast summary: Annual, All Other Regions*" -> Forecast summary: Annual, All Other Regions*
K2: Prior forecast | R2: Current compared to prior (difference)
C3: Hotel supply (daily) | D3: Hotel room demand (daily) | E3: Occupancy | F3: ADR | G3: RevPAR | H3: Room revenue | K3: Hotel supply (daily) | L3: Hotel room demand (daily) | M3: Occupancy | N3: ADR | O3: RevPAR | P3: Room revenue | R3: Hotel supply (daily) | S3: Hotel room demand (daily) | T3: Occupancy | U3: ADR | V3: RevPAR | W3: Room revenue
B4: Levels | J4: Levels
C5: =California!C5-Gateway!C5 -> 174711.24 | D5: =California!D5-Gateway!D5 -> 107076.71 | E5: =D5/C5 -> 0.61287818 | F5: =H5/(D5*365) -> #DIV/0! | G5: =(H5/365)/C5 -> #DIV/0! | H5: =California!H5-Gateway!H5 -> #DIV/0! | K5: 174711.24 | L5: 107076.71 | M5: 0.61287818 | N5: #DIV/0! | O5: #DIV/0! | P5: #DIV/0!
C6: =California!C6-Gateway!C6 -> 175757.5 | D6: =California!D6-Gateway!D6 -> 111062.61 | E6: =D6/C6 -> 0.63190819 | F6: =H6/(D6*365) -> 107.4844 | G6: =(H6/365)/C6 -> 67.920274 | H6: =California!H6-Gateway!H6 -> 4.3571867e+09 | K6: 175757.5 | L6: 111062.61 | M6: 0.63190819 | N6: 107.4844 | O6: 67.920274 | P6: 4.3571867e+09
C7: =California!C7-Gateway!C7 -> 175989.67 | D7: =California!D7-Gateway!D7 -> 116687.61 | E7: =D7/C7 -> 0.6630367 | F7: =H7/(D7*365) -> 113.03299 | G7: =(H7/365)/C7 -> 74.945017 | H7: =California!H7-Gateway!H7 -> 4.8141852e+09 | K7: 175989.67 | L7: 116687.61 | M7: 0.6630367 | N7: 113.03299 | O7: 74.945017 | P7: 4.8141852e+09
C8: =California!C8-Gateway!C8 -> 176337.17 | D8: =California!D8-Gateway!D8 -> 119135.48 | E8: =D8/C8 -> 0.67561186 | F8: =H8/(D8*365) -> 119.61483 | G8: =(H8/365)/C8 -> 80.813199 | H8: =California!H8-Gateway!H8 -> 5.2013853e+09 | K8: 176337.17 | L8: 119135.48 | M8: 0.67561186 | N8: 119.61483 | O8: 80.813199 | P8: 5.2013853e+09
C9: =California!C9-Gateway!C9 -> 177131.83 | D9: =California!D9-Gateway!D9 -> 121423.81 | E9: =D9/C9 -> 0.68549966 | F9: =H9/(D9*365) -> 123.78731 | G9: =(H9/365)/C9 -> 84.856158 | H9: =California!H9-Gateway!H9 -> 5.4862153e+09 | K9: 177131.83 | L9: 121423.81 | M9: 0.68549966 | N9: 123.78731 | O9: 84.856158 | P9: 5.4862153e+09
C10: =California!C10-Gateway!C10 -> 179946.75 | D10: =California!D10-Gateway!D10 -> 123889.46 | E10: =D10/C10 -> 0.68847846 | F10: =H10/(D10*365) -> 128.53533 | G10: =(H10/365)/C10 -> 88.493807 | H10: =California!H10-Gateway!H10 -> 5.8123231e+09 | K10: 179946.75 | L10: 123889.46 | M10: 0.68847846 | N10: 128.53533 | O10: 88.493807 | P10: 5.8123231e+09
B11: 2019 | C11: =California!C11-Gateway!C11 -> 187275.33 | D11: =California!D11-Gateway!D11 -> 128651.61 | E11: =D11/C11 -> 0.68696507 | F11: =H11/(D11*365) -> 129.23644 | G11: =(H11/365)/C11 -> 88.780917 | H11: =California!H11-Gateway!H11 -> 6.0686637e+09 | J11: 2019 | K11: 187275.33 | L11: 128651.61 | M11: 0.68696507 | N11: 129.23644 | O11: 88.780917 | P11: 6.0686637e+09
B12: 2020 | C12: =California!C12-Gateway!C12 -> 187111.92 | D12: =California!D12-Gateway!D12 -> 99488.873 | E12: =D12/C12 -> 0.53170784 | F12: =H12/(D12*365) -> 117.38185 | G12: =(H12/365)/C12 -> 62.412849 | H12: =California!H12-Gateway!H12 -> 4.2625385e+09 | J12: 2020 | K12: 187111.92 | L12: 99488.873 | M12: 0.53170784 | N12: 117.38185 | O12: 62.412849 | P12: 4.2625385e+09
B13: 2021 | C13: =California!C13-Gateway!C13 -> 194039.92 | D13: =California!D13-Gateway!D13 -> 126066.84 | E13: =D13/C13 -> 0.64969538 | F13: =H13/(D13*365) -> 145.62282 | G13: =(H13/365)/C13 -> 94.610471 | H13: =California!H13-Gateway!H13 -> 6.7007459e+09 | J13: 2021 | K13: 194039.92 | L13: 126066.84 | M13: 0.64969538 | N13: 145.62282 | O13: 94.610471 | P13: 6.7007459e+09
B14: 2022 | C14: =California!C14-Gateway!C14 -> 196951.83 | D14: =California!D14-Gateway!D14 -> 128163.9 | E14: =D14/C14 -> 0.65073727 | F14: =H14/(D14*365) -> 163.2975 | G14: =(H14/365)/C14 -> 106.26377 | H14: =California!H14-Gateway!H14 -> 7.6390283e+09 | J14: 2022 | K14: 196951.83 | L14: 128163.9 | M14: 0.65073727 | N14: 163.2975 | O14: 106.26377 | P14: 7.6390283e+09
B15: 2023 | C15: =California!C15-Gateway!C15 -> 198487.41 | D15: =California!D15-Gateway!D15 -> 124863.06 | E15: =D15/C15 -> 0.62907293 | F15: =H15/(D15*365) -> 163.69367 | G15: =(H15/365)/C15 -> 102.97525 | H15: =California!H15-Gateway!H15 -> 7.4603414e+09 | J15: 2023 | K15: 198487.41 | L15: 124863.06 | M15: 0.62907293 | N15: 163.69367 | O15: 102.97525 | P15: 7.4603414e+09
B16: 2024 | C16: =California!C16-Gateway!C16 -> 201177.17 | D16: =California!D16-Gateway!D16 -> 124531.55 | E16: =D16/C16 -> 0.61901433 | F16: =H16/(D16*365) -> 163.53421 | G16: =(H16/365)/C16 -> 101.23002 | H16: =California!H16-Gateway!H16 -> 7.4332863e+09 | J16: 2024 | K16: 201177.17 | L16: 124531.55 | M16: 0.61901433 | N16: 163.53421 | O16: 101.23002 | P16: 7.4332863e+09
B17: 2025 | C17: =California!C17-Gateway!C17 -> 203530.75 | D17: =California!D17-Gateway!D17 -> 126080.17 | E17: =D17/C17 -> 0.61946497 | F17: =H17/(D17*365) -> 164.45605 | G17: =(H17/365)/C17 -> 101.87476 | H17: =California!H17-Gateway!H17 -> 7.568146e+09 | J17: 2025 | K17: 203530.75 | L17: 126080.17 | M17: 0.61946497 | N17: 164.45605 | O17: 101.87476 | P17: 7.568146e+09 | R17: =C17-K17 -> 0 | S17: =D17-L17 -> 0 | T17: =E17-M17 -> 0 | U17: =F17-N17 -> 0 | V17: =G17-O17 -> 0 | W17: =H17-P17 -> 0
B18: 2026 | C18: =California!C18-Gateway!C18 -> 206038.29 | D18: =California!D18-Gateway!D18 -> 128734.25 | E18: =D18/C18 -> 0.6248074 | F18: =H18/(D18*365) -> 167.2906 | G18: =(H18/365)/C18 -> 104.52441 | H18: =California!H18-Gateway!H18 -> 7.860651e+09 | J18: 2026 | K18: 207699.5 | L18: 127496.15 | M18: 0.61384908 | N18: 166.0989 | O18: 101.95966 | P18: 7.729594e+09 | R18: =C18-K18 -> -1661.2083 | S18: =D18-L18 -> 1238.1018 | T18: =E18-M18 -> 0.010958317 | U18: =F18-N18 -> 1.1917021 | V18: =G18-O18 -> 2.5647487 | W18: =H18-P18 -> 1.3105698e+08
B19: 2027 | C19: =California!C19-Gateway!C19 -> 209372.73 | D19: =California!D19-Gateway!D19 -> 130349.13 | E19: =D19/C19 -> 0.62256974 | F19: =H19/(D19*365) -> 169.18307 | G19: =(H19/365)/C19 -> 105.32826 | H19: =California!H19-Gateway!H19 -> 8.0492962e+09 | J19: 2027 | K19: 210845.83 | L19: 129697.88 | M19: 0.61513136 | N19: 168.22296 | O19: 103.47922 | P19: 7.9636288e+09 | R19: =C19-K19 -> -1473.0917 | S19: =D19-L19 -> 651.24846 | T19: =E19-M19 -> 0.0074383771 | U19: =F19-N19 -> 0.96011517 | V19: =G19-O19 -> 1.8490445 | W19: =H19-P19 -> 85667368
B20: 2028 | C20: =California!C20-Gateway!C20 -> 214702.65 | D20: =California!D20-Gateway!D20 -> 132459.21 | E20: =D20/C20 -> 0.61694258 | F20: =H20/(D20*365) -> 171.99493 | G20: =(H20/365)/C20 -> 106.111 | H20: =California!H20-Gateway!H20 -> 8.3155439e+09 | J20: 2028 | K20: 213622.22 | L20: 132015.09 | M20: 0.61798387 | N20: 171.0528 | O20: 105.70787 | P20: 8.2422657e+09 | R20: =C20-K20 -> 1080.4269 | S20: =D20-L20 -> 444.11885 | T20: =E20-M20 -> -0.0010412893 | U20: =F20-N20 -> 0.94213535 | V20: =G20-O20 -> 0.40312798 | W20: =H20-P20 -> 73278230
B21: 2029 | C21: =California!C21-Gateway!C21 -> 217109.07 | D21: =California!D21-Gateway!D21 -> 134643.04 | E21: =D21/C21 -> 0.62016313 | F21: =H21/(D21*365) -> 174.86572 | G21: =(H21/365)/C21 -> 108.44527 | H21: =California!H21-Gateway!H21 -> 8.5937246e+09 | J21: 2029 | K21: 216019.59 | L21: 134144.89 | M21: 0.62098483 | N21: 174.01376 | O21: 108.0599 | P21: 8.5202155e+09 | R21: =C21-K21 -> 1089.4722 | S21: =D21-L21 -> 498.14671 | T21: =E21-M21 -> -0.00082170218 | U21: =F21-N21 -> 0.85195936 | V21: =G21-O21 -> 0.3853663 | W21: =H21-P21 -> 73509093
B23: Growth | J23: Growth
C24: =C6/C5-1 -> 0.0059885125 | D24: =D6/D5-1 -> 0.037224689 | E24: =E6/E5-1 -> 0.031050232 | F24: =F6/F5-1 -> #DIV/0! | G24: =G6/G5-1 -> #DIV/0! | H24: =H6/H5-1 -> #DIV/0!
C25: =C7/C6-1 -> 0.0013209249 | D25: =D7/D6-1 -> 0.050647112 | E25: =E7/E6-1 -> 0.049261117 | F25: =F7/F6-1 -> 0.051622226 | G25: =G7/G6-1 -> 0.10342631 | H25: =H7/H6-1 -> 0.10488386
C26: =C8/C7-1 -> 0.0019745477 | D26: =D8/D7-1 -> 0.020978019 | E26: =E8/E7-1 -> 0.018966022 | F26: =F8/F7-1 -> 0.058229426 | G26: =G8/G7-1 -> 0.078299828 | H26: =H8/H7-1 -> 0.080428983
C27: =C9/C8-1 -> 0.0045065183 | D27: =D9/D8-1 -> 0.0192078 | E27: =E9/E8-1 -> 0.014635327 | F27: =F9/F8-1 -> 0.034882598 | G27: =G9/G8-1 -> 0.050028443 | H27: =H9/H8-1 -> 0.054760416
C28: =C10/C9-1 -> 0.015891648 | D28: =D10/D9-1 -> 0.020306144 | E28: =E10/E9-1 -> 0.0043454398 | F28: =F10/F9-1 -> 0.038356304 | G28: =G10/G9-1 -> 0.042868419 | H28: =H10/H9-1 -> 0.059441316
